<?xml version="1.0" ?>
<!-- =================================================================================== -->
<!-- |    This document was autogenerated by xacro from puma560_robot.urdf.xacro       | -->
<!-- |    EDITING THIS FILE BY HAND IS NOT RECOMMENDED                                 | -->
<!-- =================================================================================== -->
<robot name="Puma560" xmlns:xacro="http://www.ros.org/wiki/xacro">
    <link name="base_link">
        
<inertial>
            <mass value="6.215" />
            <origin rpy="0 0 0" xyz="-0.04204 8.01E-05 0.07964" /> <!--mudei <origin rpy="0 0 0" xyz="-0.04204 8.01E-05 0.07964" />-->
            <inertia ixx="0.0247272" ixy="-8.0784E-05" ixz="0.00130902" iyy="0.0491285" iyz="-8.0419E-06" izz="0.0472376" />
        </inertial>

            <visual>
            <origin rpy="0 0 0" xyz="0 0 0" />
            <geometry>
                <box size="0.25 0.25 0.25" />
                <!--mudei-->
            </geometry>
            <material name="">
                <color rgba="0.7372549 0.3490196 0.1607843 1" />
            </material>
        </visual>
        <collision>
            <origin rpy="0 0 0" xyz="0 0 0" />
            <geometry>
                <box size="0.25 0.25 0.25" />
                <!--mudei-->
            </geometry>
            <material name="">
                <color rgba="1 1 0 1" />
            </material>
        </collision>
    </link>
    <link name="link_1">
        
<inertial>
            <mass value="3.067" />
            <origin rpy="0 0 0" xyz="9.77E-05 -0.00012 0.23841" />
            <inertia ixx="0.0142175" ixy="-1.28579E-05" ixz="-2.31364E-05" iyy="0.0144041" iyz="1.93404E-05" izz="0.0104533" />
        </inertial>

        <visual>
      <origin
        xyz="0 0 0"
        rpy="1.57 0 0" />
      <geometry>
        <mesh
          filename="package://robocop/meshes/Link1.STL" /> <!--filename="package://robocop/meshes/Link1.STL" />-->
      </geometry>
      <material
        name="">
        <color
          rgba="0.792156862745098 0.819607843137255 0.933333333333333 1" />
      </material>
    </visual>
        <collision>
            <origin rpy="0 0 0" xyz="0 0 0" />
            <geometry>
                <cylinder length="0.05" radius="0.05" />
                <!--mudei-->
            </geometry>
            <material name="">
                <color rgba="1 1 0 1" />
            </material>
        </collision>
    </link>
    <link name="link_2">
        
<inertial>
            <mass value="3.909" />
            <origin rpy="0 0 0" xyz="0.00078 -0.00212 0.10124" />
            <inertia ixx="0.0603111" ixy="9.83431E-06" ixz="5.72407E-05" iyy="0.041569" iyz="-0.00050497" izz="0.0259548" />
        </inertial>

        <visual>
      <origin
        xyz="0 0 0"
        rpy="-1.57 0 1.57" />
      <geometry>
        <mesh
          filename="package://robocop/meshes/Link2.STL" />
      </geometry>
      <material
        name="">
        <color
          rgba="0.792156862745098 0.819607843137255 0.933333333333333 1" />
      </material>
    </visual>
        <collision>
            <origin rpy="1.570796327 0 0" xyz="0 0 0" />
            <geometry>
                <cylinder length="0.05" radius="0.05" />
                <!--mudei-->
            </geometry>
            <material name="">
                <color rgba="1 1 0 1" />
            </material>
        </collision>
    </link>
    <link name="link_3">
        
<inertial>
            <mass value="2.944" />
            <origin rpy="0 0 0" xyz="0.02281 0.00106 0.05791" />
            <inertia ixx="0.00835606" ixy="-8.01545E-05" ixz="0.00142884" iyy="0.016713" iyz="-0.000182227" izz="0.0126984" />
        </inertial>

        <visual>
      <origin
        xyz="0 0 0"
        rpy="-1.57 0 0" />
      <geometry>
        <mesh
          filename="package://robocop/meshes/Link3.STL" />
      </geometry>
      <material
        name="">
        <color
          rgba="0.792156862745098 0.819607843137255 0.933333333333333 1" />
      </material>
    </visual>
        <collision>
            <origin rpy="1.570796327 0 0" xyz="0 0 0" />
            <geometry>
                <cylinder length="0.05" radius="0.05" />
                <!--mudei-->
            </geometry>
            <material name="">
                <color rgba="1 1 0 1" />
            </material>
        </collision>
    </link>
    <link name="link_4">
        
<inertial>
            <mass value="1.328" />
            <origin rpy="0 0 0" xyz="0.2247 0.00015 0.00041" /><!--xyz="0.2247 0.00015 0.00041"-->
            <inertia ixx="0.00284661" ixy="-2.12765E-05" ixz="-1.6435E-05" iyy="0.00401346" iyz="1.31336E-05" izz="0.0052535" />
        </inertial>

        <visual>
      <origin
        xyz="0 0.044 -0.044"
        rpy="1.57 0 0" />
      <geometry>
        <mesh
          filename="package://robocop/meshes/Link4.STL" />
      </geometry>
      <material
        name="">
        <color
          rgba="0.792156862745098 0.819607843137255 0.933333333333333 1" />
      </material>
    </visual>
        <collision>
            <origin rpy="0 0 0" xyz="0 0 0" />
            <geometry>
                <cylinder length="0.01" radius="0.02" />
                <!--mudei-->
            </geometry>
            <material name="">
                <color rgba="1 1 0 1" />
            </material>
        </collision>
    </link>
    <link name="link_5">
        
<inertial>
            <mass value="0.546" />
            <origin rpy="0 0 0" xyz="-0.00109 3.68E-05 6.22E-05" />
            <inertia ixx="0.000404891" ixy="1.61943E-06" ixz="8.46805E-07" iyy="0.000892825" iyz="-1.51792E-08" izz="0.000815468" />
        </inertial>

        <visual>
      <origin
        xyz="0 0.044 -0.044"
        rpy="1.57 0 0" />
      <geometry>
        <mesh
          filename="package://robocop/meshes/Link5.STL" />
      </geometry>
      <material
        name="">
        <color
          rgba="0.792156862745098 0.819607843137255 0.933333333333333 1" />
      </material>
    </visual>
        <collision>
            <origin rpy="1.570796327 0 0" xyz="0 0 0" />
            <geometry>
                <cylinder length="0.01" radius="0.01" />
                <!--mudei-->
            </geometry>
            <material name="">
                <color rgba="1 1 0 1" />
            </material>
        </collision>
    </link>
    <link name="link_6">
        
<inertial>
            <mass value="0.137" />
            <origin rpy="0 0 0" xyz="-0.00706 -0.00017 -1.32E-06" />
            <inertia ixx="0.001" ixy="0" ixz="0" iyy="0.001" iyz="0" izz="0.001" />
        </inertial>

        <visual>
      <origin
        xyz="0 0.044 0"
        rpy="1.57 0 0" />
      <geometry>
        <mesh
          filename="package://robocop/meshes/garra.STL" />
      </geometry>
      <material
        name="">
        <color
          rgba="0.792156862745098 0.819607843137255 0.933333333333333 1" />
      </material>
    </visual>
        <collision>
            <origin rpy="0 0 0" xyz="0 0 0" />
            <geometry>
                <cylinder length="0.02" radius="0.02" />
                <!--mudei-->
            </geometry>
            <material name="">
                <color rgba="1 1 0 1" />
            </material>
        </collision>
    </link>
    <link name="tool0" />
    <!-- end of link list -->
    <!-- joint list -->
    <joint name="joint_1" type="revolute">
        <origin rpy="0 0 0" xyz="0 0 0.15" />
        <parent link="base_link" />
        <child link="link_1" />
        <limit effort="0" lower="0" upper="3.1415" velocity="4.36332" />
        <axis xyz="0 0 1" />
        <dynamics damping="0.0" friction="0.0" />
    </joint>
    <joint name="joint_2" type="revolute">
        <origin rpy="0 0 0" xyz="0 0 0.1309" />
        <parent link="link_1" />
        <child link="link_2" />
        <limit effort="0" lower="-2.04" upper="1.1" velocity="4.36332" />
        <axis xyz="0 1 0" />
        <dynamics damping="0.0" friction="0.0" />
    </joint>
    <joint name="joint_3" type="revolute">
        <origin rpy="0 0 0" xyz="0 0 0.27" />
        <parent link="link_2" />
        <child link="link_3" />
        <limit effort="0" lower="-1.57075" upper="1.57075" velocity="4.36332" />
        <axis xyz="0 1 0" />
        <dynamics damping="0.0" friction="0.0" />
    </joint>
    <joint name="joint_4" type="revolute">
        <origin rpy="0 0 0" xyz="0 0 0.3136" /><!--xyz="0 0 -0.3136"-->
        <parent link="link_3" />
        <child link="link_4" />
        <limit effort="0" lower="0" upper="3.1415" velocity="5.58505" />
        <axis xyz="0 0 1" />
        <dynamics damping="0.0" friction="0.0" />
    </joint>
    <joint name="joint_5" type="revolute">
        <origin rpy="0 0 0" xyz="0 0 -0.022" />
        <parent link="link_4" />
        <child link="link_5" />
        <limit effort="0" lower="2.36" upper="5.5" velocity="5.58505" />
        <axis xyz="0 1 0" />
        <dynamics damping="0.0" friction="0.0" />
    </joint>
    <joint name="joint_6" type="revolute">
        <origin rpy="0 0 0" xyz="0 0 -0.0582" />
        <parent link="link_5" />
        <child link="link_6" />
        <limit effort="0" lower="0" upper="3.1415" velocity="7.33038" />
        <axis xyz="0 0 1" />
        <dynamics damping="0.0" friction="0.0" />
    </joint>
    <joint name="joint6-tool0" type="fixed">
        <parent link="link_6" />
        <child link="tool0" />
        <origin rpy="0 0 0" xyz="0 0 -0.14" />
    </joint>
    <!-- end of joint list -->
    <!-- ROS base_link to ABB World Coordinates transform -->
    <link name="base" />
    <joint name="base_link-base" type="fixed">
        <origin rpy="0 0 0" xyz="0 0 0" />
        <parent link="base_link" />
        <child link="base" />
    </joint>
    
<transmission name="trans_joint_1">
        <type>transmission_interface/SimpleTransmission</type>
        <joint name="joint_1">
            <hardwareInterface>hardware_interface/EffortJointInterface</hardwareInterface>
        </joint>
        <actuator name="joint_1_motor">
            <hardwareInterface>hardware_interface/EffortJointInterface</hardwareInterface>
            <mechanicalReduction>1</mechanicalReduction>
        </actuator>
    </transmission>
    <transmission name="trans_joint_2">
        <type>transmission_interface/SimpleTransmission</type>
        <joint name="joint_2">
            <hardwareInterface>hardware_interface/EffortJointInterface</hardwareInterface>
        </joint>
        <actuator name="joint_2_motor">
            <hardwareInterface>hardware_interface/EffortJointInterface</hardwareInterface>
            <mechanicalReduction>1</mechanicalReduction>
        </actuator>
    </transmission>
    <transmission name="trans_joint_3">
        <type>transmission_interface/SimpleTransmission</type>
        <joint name="joint_3">
            <hardwareInterface>hardware_interface/EffortJointInterface</hardwareInterface>
        </joint>
        <actuator name="joint_3_motor">
            <hardwareInterface>hardware_interface/EffortJointInterface</hardwareInterface>
            <mechanicalReduction>1</mechanicalReduction>
        </actuator>
    </transmission>
    <transmission name="trans_joint_4">
        <type>transmission_interface/SimpleTransmission</type>
        <joint name="joint_4">
            <hardwareInterface>hardware_interface/EffortJointInterface</hardwareInterface>
        </joint>
        <actuator name="joint_4_motor">
            <hardwareInterface>hardware_interface/EffortJointInterface</hardwareInterface>
            <mechanicalReduction>1</mechanicalReduction>
        </actuator>
    </transmission>
    <transmission name="trans_joint_5">
        <type>transmission_interface/SimpleTransmission</type>
        <joint name="joint_5">
            <hardwareInterface>hardware_interface/EffortJointInterface</hardwareInterface>
        </joint>
        <actuator name="joint_5_motor">
            <hardwareInterface>hardware_interface/EffortJointInterface</hardwareInterface>
            <mechanicalReduction>1</mechanicalReduction>
        </actuator>
    </transmission>
    <transmission name="trans_joint_6">
        <type>transmission_interface/SimpleTransmission</type>
        <joint name="joint_6">
            <hardwareInterface>hardware_interface/EffortJointInterface</hardwareInterface>
        </joint>
        <actuator name="joint_6_motor">
            <hardwareInterface>hardware_interface/EffortJointInterface</hardwareInterface>
            <mechanicalReduction>1</mechanicalReduction>
        </actuator>
    </transmission>
    <gazebo>
        <plugin name="gazebo_ros_control" filename="libgazebo_ros_control.so">
            <robotNamespace>/</robotNamespace>
        </plugin>
    </gazebo>
</robot>


